/home/yangc1/nigo0024/anaconda3/envs/sip_run_2/lib/python3.8/site-packages/sklearn/linear_model/_coordinate_descent.py:529: ConvergenceWarning: Objective did not converge. You might want to increase the number of iterations. Duality gap: 2390231.0894368785, tolerance: 29878.114385653145
  model = cd_fast.enet_coordinate_descent(
/home/yangc1/nigo0024/anaconda3/envs/sip_run_2/lib/python3.8/site-packages/sklearn/linear_model/_coordinate_descent.py:529: ConvergenceWarning: Objective did not converge. You might want to increase the number of iterations. Duality gap: 2483973.8217879008, tolerance: 29878.114385653145
  model = cd_fast.enet_coordinate_descent(
/home/yangc1/nigo0024/anaconda3/envs/sip_run_2/lib/python3.8/site-packages/sklearn/linear_model/_coordinate_descent.py:529: ConvergenceWarning: Objective did not converge. You might want to increase the number of iterations. Duality gap: 3314534.8725744123, tolerance: 29878.114385653145
  model = cd_fast.enet_coordinate_descent(
/home/yangc1/nigo0024/anaconda3/envs/sip_run_2/lib/python3.8/site-packages/sklearn/linear_model/_coordinate_descent.py:529: ConvergenceWarning: Objective did not converge. You might want to increase the number of iterations. Duality gap: 5410442.317451266, tolerance: 29878.114385653145
  model = cd_fast.enet_coordinate_descent(
/home/yangc1/nigo0024/anaconda3/envs/sip_run_2/lib/python3.8/site-packages/sklearn/linear_model/_coordinate_descent.py:529: ConvergenceWarning: Objective did not converge. You might want to increase the number of iterations. Duality gap: 542291.9385575876, tolerance: 29878.114385653145
  model = cd_fast.enet_coordinate_descent(
/home/yangc1/nigo0024/anaconda3/envs/sip_run_2/lib/python3.8/site-packages/sklearn/linear_model/_coordinate_descent.py:529: ConvergenceWarning: Objective did not converge. You might want to increase the number of iterations. Duality gap: 542291.9385575876, tolerance: 29878.114385653145
  model = cd_fast.enet_coordinate_descent(
/home/yangc1/nigo0024/anaconda3/envs/sip_run_2/lib/python3.8/site-packages/sklearn/linear_model/_coordinate_descent.py:529: ConvergenceWarning: Objective did not converge. You might want to increase the number of iterations. Duality gap: 542291.9385575876, tolerance: 29878.114385653145
  model = cd_fast.enet_coordinate_descent(
/home/yangc1/nigo0024/anaconda3/envs/sip_run_2/lib/python3.8/site-packages/sklearn/linear_model/_coordinate_descent.py:529: ConvergenceWarning: Objective did not converge. You might want to increase the number of iterations. Duality gap: 79517.02086880803, tolerance: 29878.114385653145
  model = cd_fast.enet_coordinate_descent(
/home/yangc1/nigo0024/anaconda3/envs/sip_run_2/lib/python3.8/site-packages/sklearn/linear_model/_coordinate_descent.py:529: ConvergenceWarning: Objective did not converge. You might want to increase the number of iterations. Duality gap: 61743.553047735244, tolerance: 29878.114385653145
  model = cd_fast.enet_coordinate_descent(
/home/yangc1/nigo0024/anaconda3/envs/sip_run_2/lib/python3.8/site-packages/sklearn/linear_model/_coordinate_descent.py:529: ConvergenceWarning: Objective did not converge. You might want to increase the number of iterations. Duality gap: 2.6035293001123136, tolerance: 1.8076350131766827
  model = cd_fast.enet_coordinate_descent(
/home/yangc1/nigo0024/anaconda3/envs/sip_run_2/lib/python3.8/site-packages/sklearn/linear_model/_coordinate_descent.py:529: ConvergenceWarning: Objective did not converge. You might want to increase the number of iterations. Duality gap: 2.5815762066788466, tolerance: 1.7373678994295898
  model = cd_fast.enet_coordinate_descent(
/home/yangc1/nigo0024/anaconda3/envs/sip_run_2/lib/python3.8/site-packages/sklearn/linear_model/_coordinate_descent.py:529: ConvergenceWarning: Objective did not converge. You might want to increase the number of iterations. Duality gap: 10.650418484184229, tolerance: 4.363814331893999
  model = cd_fast.enet_coordinate_descent(
Traceback (most recent call last):
  File "/home/yangc1/nigo0024/anaconda3/envs/sip_run_2/lib/python3.8/site-packages/pandas/core/internals/construction.py", line 564, in _list_to_arrays
    columns = _validate_or_indexify_columns(content, columns)
  File "/home/yangc1/nigo0024/anaconda3/envs/sip_run_2/lib/python3.8/site-packages/pandas/core/internals/construction.py", line 688, in _validate_or_indexify_columns
    raise AssertionError(
AssertionError: 4 columns passed, passed data had 2 columns

The above exception was the direct cause of the following exception:

Traceback (most recent call last):
  File "sip/tune_train.py", line 240, in <module>
    df_params = summarize_tuning_results(
  File "/panfs/roc/groups/5/yangc1/public/hs_process/sip/sip_functions.py", line 2464, in summarize_tuning_results
    df_params = summarize_tuning_loop(
  File "/panfs/roc/groups/5/yangc1/public/hs_process/sip/sip_functions.py", line 2444, in summarize_tuning_loop
    df_temp = pd.DataFrame(data=[data], columns=df_params.columns)
  File "/home/yangc1/nigo0024/anaconda3/envs/sip_run_2/lib/python3.8/site-packages/pandas/core/frame.py", line 509, in __init__
    arrays, columns = to_arrays(data, columns, dtype=dtype)
  File "/home/yangc1/nigo0024/anaconda3/envs/sip_run_2/lib/python3.8/site-packages/pandas/core/internals/construction.py", line 524, in to_arrays
    return _list_to_arrays(data, columns, coerce_float=coerce_float, dtype=dtype)
  File "/home/yangc1/nigo0024/anaconda3/envs/sip_run_2/lib/python3.8/site-packages/pandas/core/internals/construction.py", line 567, in _list_to_arrays
    raise ValueError(e) from e
ValueError: 4 columns passed, passed data had 2 columns
/home/yangc1/nigo0024/anaconda3/envs/sip_run_2/lib/python3.8/site-packages/sklearn/linear_model/_coordinate_descent.py:529: ConvergenceWarning: Objective did not converge. You might want to increase the number of iterations. Duality gap: 2704.3700316244526, tolerance: 17.538496504468622
  model = cd_fast.enet_coordinate_descent(
/home/yangc1/nigo0024/anaconda3/envs/sip_run_2/lib/python3.8/site-packages/sklearn/linear_model/_coordinate_descent.py:529: ConvergenceWarning: Objective did not converge. You might want to increase the number of iterations. Duality gap: 4592.740397659976, tolerance: 17.538496504468622
  model = cd_fast.enet_coordinate_descent(
/home/yangc1/nigo0024/anaconda3/envs/sip_run_2/lib/python3.8/site-packages/sklearn/linear_model/_coordinate_descent.py:529: ConvergenceWarning: Objective did not converge. You might want to increase the number of iterations. Duality gap: 2713.610928792801, tolerance: 17.538496504468622
  model = cd_fast.enet_coordinate_descent(
Traceback (most recent call last):
  File "/home/yangc1/nigo0024/anaconda3/envs/sip_run_2/lib/python3.8/site-packages/pandas/core/internals/construction.py", line 564, in _list_to_arrays
    columns = _validate_or_indexify_columns(content, columns)
  File "/home/yangc1/nigo0024/anaconda3/envs/sip_run_2/lib/python3.8/site-packages/pandas/core/internals/construction.py", line 688, in _validate_or_indexify_columns
    raise AssertionError(
AssertionError: 4 columns passed, passed data had 2 columns

The above exception was the direct cause of the following exception:

Traceback (most recent call last):
  File "sip/tune_train.py", line 240, in <module>
    df_params = summarize_tuning_results(
  File "/panfs/roc/groups/5/yangc1/public/hs_process/sip/sip_functions.py", line 2464, in summarize_tuning_results
    df_params = summarize_tuning_loop(
  File "/panfs/roc/groups/5/yangc1/public/hs_process/sip/sip_functions.py", line 2444, in summarize_tuning_loop
    df_temp = pd.DataFrame(data=[data], columns=df_params.columns)
  File "/home/yangc1/nigo0024/anaconda3/envs/sip_run_2/lib/python3.8/site-packages/pandas/core/frame.py", line 509, in __init__
    arrays, columns = to_arrays(data, columns, dtype=dtype)
  File "/home/yangc1/nigo0024/anaconda3/envs/sip_run_2/lib/python3.8/site-packages/pandas/core/internals/construction.py", line 524, in to_arrays
    return _list_to_arrays(data, columns, coerce_float=coerce_float, dtype=dtype)
  File "/home/yangc1/nigo0024/anaconda3/envs/sip_run_2/lib/python3.8/site-packages/pandas/core/internals/construction.py", line 567, in _list_to_arrays
    raise ValueError(e) from e
ValueError: 4 columns passed, passed data had 2 columns
/home/yangc1/nigo0024/anaconda3/envs/sip_run_2/lib/python3.8/site-packages/sklearn/linear_model/_coordinate_descent.py:529: ConvergenceWarning: Objective did not converge. You might want to increase the number of iterations. Duality gap: 6.258016975339784, tolerance: 0.011853163025327513
  model = cd_fast.enet_coordinate_descent(
/home/yangc1/nigo0024/anaconda3/envs/sip_run_2/lib/python3.8/site-packages/sklearn/linear_model/_coordinate_descent.py:529: ConvergenceWarning: Objective did not converge. You might want to increase the number of iterations. Duality gap: 0.28020253382026894, tolerance: 0.011853163025327513
  model = cd_fast.enet_coordinate_descent(
/home/yangc1/nigo0024/anaconda3/envs/sip_run_2/lib/python3.8/site-packages/sklearn/feature_selection/_base.py:79: UserWarning: No features were selected: either the data is too noisy or the selection test too strict.
  warn("No features were selected: either the data is"
/home/yangc1/nigo0024/anaconda3/envs/sip_run_2/lib/python3.8/site-packages/sklearn/feature_selection/_base.py:79: UserWarning: No features were selected: either the data is too noisy or the selection test too strict.
  warn("No features were selected: either the data is"
/home/yangc1/nigo0024/anaconda3/envs/sip_run_2/lib/python3.8/site-packages/sklearn/feature_selection/_base.py:79: UserWarning: No features were selected: either the data is too noisy or the selection test too strict.
  warn("No features were selected: either the data is"
/home/yangc1/nigo0024/anaconda3/envs/sip_run_2/lib/python3.8/site-packages/sklearn/feature_selection/_base.py:79: UserWarning: No features were selected: either the data is too noisy or the selection test too strict.
  warn("No features were selected: either the data is"
/home/yangc1/nigo0024/anaconda3/envs/sip_run_2/lib/python3.8/site-packages/sklearn/feature_selection/_base.py:79: UserWarning: No features were selected: either the data is too noisy or the selection test too strict.
  warn("No features were selected: either the data is"
/home/yangc1/nigo0024/anaconda3/envs/sip_run_2/lib/python3.8/site-packages/sklearn/feature_selection/_base.py:79: UserWarning: No features were selected: either the data is too noisy or the selection test too strict.
  warn("No features were selected: either the data is"
/home/yangc1/nigo0024/anaconda3/envs/sip_run_2/lib/python3.8/site-packages/sklearn/feature_selection/_base.py:79: UserWarning: No features were selected: either the data is too noisy or the selection test too strict.
  warn("No features were selected: either the data is"
/home/yangc1/nigo0024/anaconda3/envs/sip_run_2/lib/python3.8/site-packages/sklearn/feature_selection/_base.py:79: UserWarning: No features were selected: either the data is too noisy or the selection test too strict.
  warn("No features were selected: either the data is"
/home/yangc1/nigo0024/anaconda3/envs/sip_run_2/lib/python3.8/site-packages/sklearn/feature_selection/_base.py:79: UserWarning: No features were selected: either the data is too noisy or the selection test too strict.
  warn("No features were selected: either the data is"
/home/yangc1/nigo0024/anaconda3/envs/sip_run_2/lib/python3.8/site-packages/sklearn/feature_selection/_base.py:79: UserWarning: No features were selected: either the data is too noisy or the selection test too strict.
  warn("No features were selected: either the data is"
/home/yangc1/nigo0024/anaconda3/envs/sip_run_2/lib/python3.8/site-packages/sklearn/feature_selection/_base.py:79: UserWarning: No features were selected: either the data is too noisy or the selection test too strict.
  warn("No features were selected: either the data is"
/home/yangc1/nigo0024/anaconda3/envs/sip_run_2/lib/python3.8/site-packages/sklearn/feature_selection/_base.py:79: UserWarning: No features were selected: either the data is too noisy or the selection test too strict.
  warn("No features were selected: either the data is"
/home/yangc1/nigo0024/anaconda3/envs/sip_run_2/lib/python3.8/site-packages/sklearn/feature_selection/_base.py:79: UserWarning: No features were selected: either the data is too noisy or the selection test too strict.
  warn("No features were selected: either the data is"
/home/yangc1/nigo0024/anaconda3/envs/sip_run_2/lib/python3.8/site-packages/sklearn/feature_selection/_base.py:79: UserWarning: No features were selected: either the data is too noisy or the selection test too strict.
  warn("No features were selected: either the data is"
/home/yangc1/nigo0024/anaconda3/envs/sip_run_2/lib/python3.8/site-packages/sklearn/feature_selection/_base.py:79: UserWarning: No features were selected: either the data is too noisy or the selection test too strict.
  warn("No features were selected: either the data is"
/home/yangc1/nigo0024/anaconda3/envs/sip_run_2/lib/python3.8/site-packages/sklearn/feature_selection/_base.py:79: UserWarning: No features were selected: either the data is too noisy or the selection test too strict.
  warn("No features were selected: either the data is"
Traceback (most recent call last):
  File "/home/yangc1/nigo0024/anaconda3/envs/sip_run_2/lib/python3.8/site-packages/pandas/core/internals/construction.py", line 564, in _list_to_arrays
    columns = _validate_or_indexify_columns(content, columns)
  File "/home/yangc1/nigo0024/anaconda3/envs/sip_run_2/lib/python3.8/site-packages/pandas/core/internals/construction.py", line 688, in _validate_or_indexify_columns
    raise AssertionError(
AssertionError: 4 columns passed, passed data had 2 columns

The above exception was the direct cause of the following exception:

Traceback (most recent call last):
  File "sip/tune_train.py", line 240, in <module>
    df_params = summarize_tuning_results(
  File "/panfs/roc/groups/5/yangc1/public/hs_process/sip/sip_functions.py", line 2464, in summarize_tuning_results
    df_params = summarize_tuning_loop(
  File "/panfs/roc/groups/5/yangc1/public/hs_process/sip/sip_functions.py", line 2444, in summarize_tuning_loop
    df_temp = pd.DataFrame(data=[data], columns=df_params.columns)
  File "/home/yangc1/nigo0024/anaconda3/envs/sip_run_2/lib/python3.8/site-packages/pandas/core/frame.py", line 509, in __init__
    arrays, columns = to_arrays(data, columns, dtype=dtype)
  File "/home/yangc1/nigo0024/anaconda3/envs/sip_run_2/lib/python3.8/site-packages/pandas/core/internals/construction.py", line 524, in to_arrays
    return _list_to_arrays(data, columns, coerce_float=coerce_float, dtype=dtype)
  File "/home/yangc1/nigo0024/anaconda3/envs/sip_run_2/lib/python3.8/site-packages/pandas/core/internals/construction.py", line 567, in _list_to_arrays
    raise ValueError(e) from e
ValueError: 4 columns passed, passed data had 2 columns
/home/yangc1/nigo0024/anaconda3/envs/sip_run_2/lib/python3.8/site-packages/sklearn/linear_model/_coordinate_descent.py:529: ConvergenceWarning: Objective did not converge. You might want to increase the number of iterations. Duality gap: 240883.23362189508, tolerance: 29878.114385653145
  model = cd_fast.enet_coordinate_descent(
/home/yangc1/nigo0024/anaconda3/envs/sip_run_2/lib/python3.8/site-packages/sklearn/linear_model/_coordinate_descent.py:529: ConvergenceWarning: Objective did not converge. You might want to increase the number of iterations. Duality gap: 836887.4191275282, tolerance: 29878.114385653145
  model = cd_fast.enet_coordinate_descent(
/home/yangc1/nigo0024/anaconda3/envs/sip_run_2/lib/python3.8/site-packages/sklearn/linear_model/_coordinate_descent.py:529: ConvergenceWarning: Objective did not converge. You might want to increase the number of iterations. Duality gap: 2805449.2739842804, tolerance: 29878.114385653145
  model = cd_fast.enet_coordinate_descent(
Traceback (most recent call last):
  File "/home/yangc1/nigo0024/anaconda3/envs/sip_run_2/lib/python3.8/site-packages/pandas/core/internals/construction.py", line 564, in _list_to_arrays
    columns = _validate_or_indexify_columns(content, columns)
  File "/home/yangc1/nigo0024/anaconda3/envs/sip_run_2/lib/python3.8/site-packages/pandas/core/internals/construction.py", line 688, in _validate_or_indexify_columns
    raise AssertionError(
AssertionError: 4 columns passed, passed data had 2 columns

The above exception was the direct cause of the following exception:

Traceback (most recent call last):
  File "sip/tune_train.py", line 240, in <module>
    df_params = summarize_tuning_results(
  File "/panfs/roc/groups/5/yangc1/public/hs_process/sip/sip_functions.py", line 2464, in summarize_tuning_results
    df_params = summarize_tuning_loop(
  File "/panfs/roc/groups/5/yangc1/public/hs_process/sip/sip_functions.py", line 2444, in summarize_tuning_loop
    df_temp = pd.DataFrame(data=[data], columns=df_params.columns)
  File "/home/yangc1/nigo0024/anaconda3/envs/sip_run_2/lib/python3.8/site-packages/pandas/core/frame.py", line 509, in __init__
    arrays, columns = to_arrays(data, columns, dtype=dtype)
  File "/home/yangc1/nigo0024/anaconda3/envs/sip_run_2/lib/python3.8/site-packages/pandas/core/internals/construction.py", line 524, in to_arrays
    return _list_to_arrays(data, columns, coerce_float=coerce_float, dtype=dtype)
  File "/home/yangc1/nigo0024/anaconda3/envs/sip_run_2/lib/python3.8/site-packages/pandas/core/internals/construction.py", line 567, in _list_to_arrays
    raise ValueError(e) from e
ValueError: 4 columns passed, passed data had 2 columns
/home/yangc1/nigo0024/anaconda3/envs/sip_run_2/lib/python3.8/site-packages/sklearn/linear_model/_coordinate_descent.py:529: ConvergenceWarning: Objective did not converge. You might want to increase the number of iterations. Duality gap: 1235.9141400161836, tolerance: 17.538496504468622
  model = cd_fast.enet_coordinate_descent(
Traceback (most recent call last):
  File "/home/yangc1/nigo0024/anaconda3/envs/sip_run_2/lib/python3.8/site-packages/pandas/core/internals/construction.py", line 564, in _list_to_arrays
    columns = _validate_or_indexify_columns(content, columns)
  File "/home/yangc1/nigo0024/anaconda3/envs/sip_run_2/lib/python3.8/site-packages/pandas/core/internals/construction.py", line 688, in _validate_or_indexify_columns
    raise AssertionError(
AssertionError: 4 columns passed, passed data had 2 columns

The above exception was the direct cause of the following exception:

Traceback (most recent call last):
  File "sip/tune_train.py", line 240, in <module>
    df_params = summarize_tuning_results(
  File "/panfs/roc/groups/5/yangc1/public/hs_process/sip/sip_functions.py", line 2464, in summarize_tuning_results
    df_params = summarize_tuning_loop(
  File "/panfs/roc/groups/5/yangc1/public/hs_process/sip/sip_functions.py", line 2444, in summarize_tuning_loop
    df_temp = pd.DataFrame(data=[data], columns=df_params.columns)
  File "/home/yangc1/nigo0024/anaconda3/envs/sip_run_2/lib/python3.8/site-packages/pandas/core/frame.py", line 509, in __init__
    arrays, columns = to_arrays(data, columns, dtype=dtype)
  File "/home/yangc1/nigo0024/anaconda3/envs/sip_run_2/lib/python3.8/site-packages/pandas/core/internals/construction.py", line 524, in to_arrays
    return _list_to_arrays(data, columns, coerce_float=coerce_float, dtype=dtype)
  File "/home/yangc1/nigo0024/anaconda3/envs/sip_run_2/lib/python3.8/site-packages/pandas/core/internals/construction.py", line 567, in _list_to_arrays
    raise ValueError(e) from e
ValueError: 4 columns passed, passed data had 2 columns
Traceback (most recent call last):
  File "/home/yangc1/nigo0024/anaconda3/envs/sip_run_2/lib/python3.8/site-packages/pandas/core/internals/construction.py", line 564, in _list_to_arrays
    columns = _validate_or_indexify_columns(content, columns)
  File "/home/yangc1/nigo0024/anaconda3/envs/sip_run_2/lib/python3.8/site-packages/pandas/core/internals/construction.py", line 688, in _validate_or_indexify_columns
    raise AssertionError(
AssertionError: 4 columns passed, passed data had 2 columns

The above exception was the direct cause of the following exception:

Traceback (most recent call last):
  File "sip/tune_train.py", line 240, in <module>
    df_params = summarize_tuning_results(
  File "/panfs/roc/groups/5/yangc1/public/hs_process/sip/sip_functions.py", line 2464, in summarize_tuning_results
    df_params = summarize_tuning_loop(
  File "/panfs/roc/groups/5/yangc1/public/hs_process/sip/sip_functions.py", line 2444, in summarize_tuning_loop
    df_temp = pd.DataFrame(data=[data], columns=df_params.columns)
  File "/home/yangc1/nigo0024/anaconda3/envs/sip_run_2/lib/python3.8/site-packages/pandas/core/frame.py", line 509, in __init__
    arrays, columns = to_arrays(data, columns, dtype=dtype)
  File "/home/yangc1/nigo0024/anaconda3/envs/sip_run_2/lib/python3.8/site-packages/pandas/core/internals/construction.py", line 524, in to_arrays
    return _list_to_arrays(data, columns, coerce_float=coerce_float, dtype=dtype)
  File "/home/yangc1/nigo0024/anaconda3/envs/sip_run_2/lib/python3.8/site-packages/pandas/core/internals/construction.py", line 567, in _list_to_arrays
    raise ValueError(e) from e
ValueError: 4 columns passed, passed data had 2 columns
/home/yangc1/nigo0024/anaconda3/envs/sip_run_2/lib/python3.8/site-packages/sklearn/linear_model/_coordinate_descent.py:529: ConvergenceWarning: Objective did not converge. You might want to increase the number of iterations. Duality gap: 326171.54065821425, tolerance: 29878.114385653145
  model = cd_fast.enet_coordinate_descent(
/home/yangc1/nigo0024/anaconda3/envs/sip_run_2/lib/python3.8/site-packages/sklearn/linear_model/_coordinate_descent.py:529: ConvergenceWarning: Objective did not converge. You might want to increase the number of iterations. Duality gap: 872217.1925926714, tolerance: 29878.114385653145
  model = cd_fast.enet_coordinate_descent(
Traceback (most recent call last):
  File "/home/yangc1/nigo0024/anaconda3/envs/sip_run_2/lib/python3.8/site-packages/pandas/core/internals/construction.py", line 564, in _list_to_arrays
    columns = _validate_or_indexify_columns(content, columns)
  File "/home/yangc1/nigo0024/anaconda3/envs/sip_run_2/lib/python3.8/site-packages/pandas/core/internals/construction.py", line 688, in _validate_or_indexify_columns
    raise AssertionError(
AssertionError: 4 columns passed, passed data had 2 columns

The above exception was the direct cause of the following exception:

Traceback (most recent call last):
  File "sip/tune_train.py", line 240, in <module>
    df_params = summarize_tuning_results(
  File "/panfs/roc/groups/5/yangc1/public/hs_process/sip/sip_functions.py", line 2464, in summarize_tuning_results
    df_params = summarize_tuning_loop(
  File "/panfs/roc/groups/5/yangc1/public/hs_process/sip/sip_functions.py", line 2444, in summarize_tuning_loop
    df_temp = pd.DataFrame(data=[data], columns=df_params.columns)
  File "/home/yangc1/nigo0024/anaconda3/envs/sip_run_2/lib/python3.8/site-packages/pandas/core/frame.py", line 509, in __init__
    arrays, columns = to_arrays(data, columns, dtype=dtype)
  File "/home/yangc1/nigo0024/anaconda3/envs/sip_run_2/lib/python3.8/site-packages/pandas/core/internals/construction.py", line 524, in to_arrays
    return _list_to_arrays(data, columns, coerce_float=coerce_float, dtype=dtype)
  File "/home/yangc1/nigo0024/anaconda3/envs/sip_run_2/lib/python3.8/site-packages/pandas/core/internals/construction.py", line 567, in _list_to_arrays
    raise ValueError(e) from e
ValueError: 4 columns passed, passed data had 2 columns
/home/yangc1/nigo0024/anaconda3/envs/sip_run_2/lib/python3.8/site-packages/sklearn/linear_model/_coordinate_descent.py:529: ConvergenceWarning: Objective did not converge. You might want to increase the number of iterations. Duality gap: 2184.848616765406, tolerance: 17.538496504468622
  model = cd_fast.enet_coordinate_descent(
/home/yangc1/nigo0024/anaconda3/envs/sip_run_2/lib/python3.8/site-packages/sklearn/linear_model/_coordinate_descent.py:529: ConvergenceWarning: Objective did not converge. You might want to increase the number of iterations. Duality gap: 939.5385933522057, tolerance: 17.538496504468622
  model = cd_fast.enet_coordinate_descent(
Traceback (most recent call last):
  File "/home/yangc1/nigo0024/anaconda3/envs/sip_run_2/lib/python3.8/site-packages/pandas/core/internals/construction.py", line 564, in _list_to_arrays
    columns = _validate_or_indexify_columns(content, columns)
  File "/home/yangc1/nigo0024/anaconda3/envs/sip_run_2/lib/python3.8/site-packages/pandas/core/internals/construction.py", line 688, in _validate_or_indexify_columns
    raise AssertionError(
AssertionError: 4 columns passed, passed data had 2 columns

The above exception was the direct cause of the following exception:

Traceback (most recent call last):
  File "sip/tune_train.py", line 240, in <module>
    df_params = summarize_tuning_results(
  File "/panfs/roc/groups/5/yangc1/public/hs_process/sip/sip_functions.py", line 2464, in summarize_tuning_results
    df_params = summarize_tuning_loop(
  File "/panfs/roc/groups/5/yangc1/public/hs_process/sip/sip_functions.py", line 2444, in summarize_tuning_loop
    df_temp = pd.DataFrame(data=[data], columns=df_params.columns)
  File "/home/yangc1/nigo0024/anaconda3/envs/sip_run_2/lib/python3.8/site-packages/pandas/core/frame.py", line 509, in __init__
    arrays, columns = to_arrays(data, columns, dtype=dtype)
  File "/home/yangc1/nigo0024/anaconda3/envs/sip_run_2/lib/python3.8/site-packages/pandas/core/internals/construction.py", line 524, in to_arrays
    return _list_to_arrays(data, columns, coerce_float=coerce_float, dtype=dtype)
  File "/home/yangc1/nigo0024/anaconda3/envs/sip_run_2/lib/python3.8/site-packages/pandas/core/internals/construction.py", line 567, in _list_to_arrays
    raise ValueError(e) from e
ValueError: 4 columns passed, passed data had 2 columns
Traceback (most recent call last):
  File "/home/yangc1/nigo0024/anaconda3/envs/sip_run_2/lib/python3.8/site-packages/pandas/core/internals/construction.py", line 564, in _list_to_arrays
    columns = _validate_or_indexify_columns(content, columns)
  File "/home/yangc1/nigo0024/anaconda3/envs/sip_run_2/lib/python3.8/site-packages/pandas/core/internals/construction.py", line 688, in _validate_or_indexify_columns
    raise AssertionError(
AssertionError: 4 columns passed, passed data had 2 columns

The above exception was the direct cause of the following exception:

Traceback (most recent call last):
  File "sip/tune_train.py", line 240, in <module>
    df_params = summarize_tuning_results(
  File "/panfs/roc/groups/5/yangc1/public/hs_process/sip/sip_functions.py", line 2464, in summarize_tuning_results
    df_params = summarize_tuning_loop(
  File "/panfs/roc/groups/5/yangc1/public/hs_process/sip/sip_functions.py", line 2444, in summarize_tuning_loop
    df_temp = pd.DataFrame(data=[data], columns=df_params.columns)
  File "/home/yangc1/nigo0024/anaconda3/envs/sip_run_2/lib/python3.8/site-packages/pandas/core/frame.py", line 509, in __init__
    arrays, columns = to_arrays(data, columns, dtype=dtype)
  File "/home/yangc1/nigo0024/anaconda3/envs/sip_run_2/lib/python3.8/site-packages/pandas/core/internals/construction.py", line 524, in to_arrays
    return _list_to_arrays(data, columns, coerce_float=coerce_float, dtype=dtype)
  File "/home/yangc1/nigo0024/anaconda3/envs/sip_run_2/lib/python3.8/site-packages/pandas/core/internals/construction.py", line 567, in _list_to_arrays
    raise ValueError(e) from e
ValueError: 4 columns passed, passed data had 2 columns
